Traceback (most recent call last):
  File "/usr/local/bin/uvicorn", line 7, in <module>
    sys.exit(main())
             ~~~~^^
  File "/usr/local/lib/python3.13/site-packages/click/core.py", line 1442, in __call__
    return self.main(*args, **kwargs)
           ~~~~~~~~~^^^^^^^^^^^^^^^^^
  File "/usr/local/lib/python3.13/site-packages/click/core.py", line 1363, in main
    rv = self.invoke(ctx)
  File "/usr/local/lib/python3.13/site-packages/click/core.py", line 1226, in invoke
    return ctx.invoke(self.callback, **ctx.params)
           ~~~~~~~~~~^^^^^^^^^^^^^^^^^^^^^^^^^^^^^
  File "/usr/local/lib/python3.13/site-packages/click/core.py", line 794, in invoke
    return callback(*args, **kwargs)
  File "/usr/local/lib/python3.13/site-packages/uvicorn/main.py", line 413, in main
    run(
    ~~~^
        app,
        ^^^^
    ...<45 lines>...
        h11_max_incomplete_event_size=h11_max_incomplete_event_size,
        ^^^^^^^^^^^^^^^^^^^^^^^^^^^^^^^^^^^^^^^^^^^^^^^^^^^^^^^^^^^^
    )
    ^
  File "/usr/local/lib/python3.13/site-packages/uvicorn/main.py", line 580, in run
    server.run()
    ~~~~~~~~~~^^
  File "/usr/local/lib/python3.13/site-packages/uvicorn/server.py", line 66, in run
    return asyncio.run(self.serve(sockets=sockets))
           ~~~~~~~~~~~^^^^^^^^^^^^^^^^^^^^^^^^^^^^^
  File "/usr/local/lib/python3.13/asyncio/runners.py", line 195, in run
    return runner.run(main)
           ~~~~~~~~~~^^^^^^
  File "/usr/local/lib/python3.13/asyncio/runners.py", line 118, in run
    return self._loop.run_until_complete(task)
           ~~~~~~~~~~~~~~~~~~~~~~~~~~~~~^^^^^^
  File "/usr/local/lib/python3.13/asyncio/base_events.py", line 725, in run_until_complete
    return future.result()
           ~~~~~~~~~~~~~^^
  File "/usr/local/lib/python3.13/site-packages/uvicorn/server.py", line 70, in serve
    await self._serve(sockets)
  File "/usr/local/lib/python3.13/site-packages/uvicorn/server.py", line 77, in _serve
    config.load()
    ~~~~~~~~~~~^^
  File "/usr/local/lib/python3.13/site-packages/uvicorn/config.py", line 435, in load
    self.loaded_app = import_from_string(self.app)
                      ~~~~~~~~~~~~~~~~~~^^^^^^^^^^
  File "/usr/local/lib/python3.13/site-packages/uvicorn/importer.py", line 19, in import_from_string
    module = importlib.import_module(module_str)
  File "/usr/local/lib/python3.13/importlib/__init__.py", line 88, in import_module
    return _bootstrap._gcd_import(name[level:], package, level)
           ~~~~~~~~~~~~~~~~~~~~~~^^^^^^^^^^^^^^^^^^^^^^^^^^^^^^
  File "<frozen importlib._bootstrap>", line 1387, in _gcd_import
  File "<frozen importlib._bootstrap>", line 1360, in _find_and_load
  File "<frozen importlib._bootstrap>", line 1331, in _find_and_load_unlocked
  File "<frozen importlib._bootstrap>", line 935, in _load_unlocked
  File "<frozen importlib._bootstrap_external>", line 1026, in exec_module
  File "<frozen importlib._bootstrap>", line 488, in _call_with_frames_removed
  File "/app/app/client.py", line 62, in <module>
    from app.routes.auth_routes import router as auth_router
  File "/app/app/routes/auth_routes.py", line 18, in <module>
    from app.models import User, UserActivity, DatabaseConnection, TestConfiguration
  File "/app/app/models.py", line 213, in <module>
    class UserActivity(Base):
    ...<53 lines>...
            }
  File "/usr/local/lib/python3.13/site-packages/sqlalchemy/orm/decl_api.py", line 198, in __init__
    _as_declarative(reg, cls, dict_)
    ~~~~~~~~~~~~~~~^^^^^^^^^^^^^^^^^
  File "/usr/local/lib/python3.13/site-packages/sqlalchemy/orm/decl_base.py", line 245, in _as_declarative
    return _MapperConfig.setup_mapping(registry, cls, dict_, None, {})
           ~~~~~~~~~~~~~~~~~~~~~~~~~~~^^^^^^^^^^^^^^^^^^^^^^^^^^^^^^^^
  File "/usr/local/lib/python3.13/site-packages/sqlalchemy/orm/decl_base.py", line 326, in setup_mapping
    return _ClassScanMapperConfig(
        registry, cls_, dict_, table, mapper_kw
    )
  File "/usr/local/lib/python3.13/site-packages/sqlalchemy/orm/decl_base.py", line 573, in __init__
    self._extract_mappable_attributes()
    ~~~~~~~~~~~~~~~~~~~~~~~~~~~~~~~~~^^
  File "/usr/local/lib/python3.13/site-packages/sqlalchemy/orm/decl_base.py", line 1530, in _extract_mappable_attributes
    raise exc.InvalidRequestError(
    ...<2 lines>...
    )
sqlalchemy.exc.InvalidRequestError: Attribute name 'metadata' is reserved when using the Declarative API.
