INFO:     POST /save-connection - Saving new database connection configuration
DEBUG:    Connection data received, validating required fields
DEBUG:    All required fields present, saving connection to DB
ERROR:    Error saving connection: 'connection_name' is an invalid keyword argument for DatabaseConnection
Traceback (most recent call last):
  File "/app/app/routes/db_routes.py", line 259, in save_connection
    connection_id = _persist_saved_connections(current_user.id, data, db)
  File "/app/app/routes/db_routes.py", line 71, in _persist_saved_connections
    new_conn = DBConnection(
        user_id=user_id,
    ...<6 lines>...
        db_name=conn_data['database']
    )
  File "<string>", line 4, in __init__
  File "/usr/local/lib/python3.13/site-packages/sqlalchemy/orm/state.py", line 571, in _initialize_instance
    with util.safe_reraise():
         ~~~~~~~~~~~~~~~~~^^
  File "/usr/local/lib/python3.13/site-packages/sqlalchemy/util/langhelpers.py", line 224, in __exit__
    raise exc_value.with_traceback(exc_tb)
  File "/usr/local/lib/python3.13/site-packages/sqlalchemy/orm/state.py", line 569, in _initialize_instance
    manager.original_init(*mixed[1:], **kwargs)
    ~~~~~~~~~~~~~~~~~~~~~^^^^^^^^^^^^^^^^^^^^^^
  File "/usr/local/lib/python3.13/site-packages/sqlalchemy/orm/decl_base.py", line 2179, in _declarative_constructor
    raise TypeError(
        "%r is an invalid keyword argument for %s" % (k, cls_.__name__)
    )
TypeError: 'connection_name' is an invalid keyword argument for DatabaseConnection
