ERROR:    Traceback (most recent call last):
  File "/usr/local/lib/python3.13/site-packages/sqlalchemy/engine/base.py", line 1967, in _exec_single_context
    self.dialect.do_execute(
    ~~~~~~~~~~~~~~~~~~~~~~~^
        cursor, str_statement, effective_parameters, context
        ^^^^^^^^^^^^^^^^^^^^^^^^^^^^^^^^^^^^^^^^^^^^^^^^^^^^
    )
    ^
  File "/usr/local/lib/python3.13/site-packages/sqlalchemy/engine/default.py", line 951, in do_execute
    cursor.execute(statement, parameters)
    ~~~~~~~~~~~~~~^^^^^^^^^^^^^^^^^^^^^^^
psycopg2.errors.DuplicateTable: relation "idx_timestamp" already exists
The above exception was the direct cause of the following exception:
Traceback (most recent call last):
  File "/usr/local/lib/python3.13/site-packages/starlette/routing.py", line 692, in lifespan
    async with self.lifespan_context(app) as maybe_state:
               ~~~~~~~~~~~~~~~~~~~~~^^^^^
  File "/usr/local/lib/python3.13/contextlib.py", line 214, in __aenter__
    return await anext(self.gen)
           ^^^^^^^^^^^^^^^^^^^^^
  File "/usr/local/lib/python3.13/site-packages/fastapi/routing.py", line 133, in merged_lifespan
    async with original_context(app) as maybe_original_state:
               ~~~~~~~~~~~~~~~~^^^^^
  File "/usr/local/lib/python3.13/contextlib.py", line 214, in __aenter__
    return await anext(self.gen)
           ^^^^^^^^^^^^^^^^^^^^^
  File "/usr/local/lib/python3.13/site-packages/fastapi/routing.py", line 133, in merged_lifespan
    async with original_context(app) as maybe_original_state:
               ~~~~~~~~~~~~~~~~^^^^^
  File "/usr/local/lib/python3.13/contextlib.py", line 214, in __aenter__
    return await anext(self.gen)
           ^^^^^^^^^^^^^^^^^^^^^
  File "/usr/local/lib/python3.13/site-packages/fastapi/routing.py", line 133, in merged_lifespan
    async with original_context(app) as maybe_original_state:
               ~~~~~~~~~~~~~~~~^^^^^
  File "/usr/local/lib/python3.13/contextlib.py", line 214, in __aenter__
    return await anext(self.gen)
           ^^^^^^^^^^^^^^^^^^^^^
  File "/usr/local/lib/python3.13/site-packages/fastapi/routing.py", line 133, in merged_lifespan
    async with original_context(app) as maybe_original_state:
               ~~~~~~~~~~~~~~~~^^^^^
  File "/usr/local/lib/python3.13/contextlib.py", line 214, in __aenter__
    return await anext(self.gen)
           ^^^^^^^^^^^^^^^^^^^^^
  File "/usr/local/lib/python3.13/site-packages/fastapi/routing.py", line 133, in merged_lifespan
    async with original_context(app) as maybe_original_state:
               ~~~~~~~~~~~~~~~~^^^^^
  File "/usr/local/lib/python3.13/contextlib.py", line 214, in __aenter__
    return await anext(self.gen)
           ^^^^^^^^^^^^^^^^^^^^^
  File "/usr/local/lib/python3.13/site-packages/fastapi/routing.py", line 133, in merged_lifespan
    async with original_context(app) as maybe_original_state:
               ~~~~~~~~~~~~~~~~^^^^^
  File "/usr/local/lib/python3.13/contextlib.py", line 214, in __aenter__
    return await anext(self.gen)
           ^^^^^^^^^^^^^^^^^^^^^
  File "/usr/local/lib/python3.13/site-packages/fastapi/routing.py", line 133, in merged_lifespan
    async with original_context(app) as maybe_original_state:
               ~~~~~~~~~~~~~~~~^^^^^
  File "/usr/local/lib/python3.13/contextlib.py", line 214, in __aenter__
    return await anext(self.gen)
           ^^^^^^^^^^^^^^^^^^^^^
  File "/usr/local/lib/python3.13/site-packages/fastapi/routing.py", line 133, in merged_lifespan
    async with original_context(app) as maybe_original_state:
               ~~~~~~~~~~~~~~~~^^^^^
  File "/usr/local/lib/python3.13/site-packages/starlette/routing.py", line 569, in __aenter__
    await self._router.startup()
  File "/usr/local/lib/python3.13/site-packages/starlette/routing.py", line 669, in startup
    await handler()
  File "/app/app/client.py", line 146, in startup_event
    init_db()
    ~~~~~~~^^
  File "/app/app/database.py", line 70, in init_db
    Base.metadata.create_all(engine)
    ~~~~~~~~~~~~~~~~~~~~~~~~^^^^^^^^
  File "/usr/local/lib/python3.13/site-packages/sqlalchemy/sql/schema.py", line 5924, in create_all
    bind._run_ddl_visitor(
    ~~~~~~~~~~~~~~~~~~~~~^
        ddl.SchemaGenerator, self, checkfirst=checkfirst, tables=tables
        ^^^^^^^^^^^^^^^^^^^^^^^^^^^^^^^^^^^^^^^^^^^^^^^^^^^^^^^^^^^^^^^
    )
    ^
  File "/usr/local/lib/python3.13/site-packages/sqlalchemy/engine/base.py", line 3252, in _run_ddl_visitor
    conn._run_ddl_visitor(visitorcallable, element, **kwargs)
    ~~~~~~~~~~~~~~~~~~~~~^^^^^^^^^^^^^^^^^^^^^^^^^^^^^^^^^^^^
  File "/usr/local/lib/python3.13/site-packages/sqlalchemy/engine/base.py", line 2459, in _run_ddl_visitor
    ).traverse_single(element)
      ~~~~~~~~~~~~~~~^^^^^^^^^
  File "/usr/local/lib/python3.13/site-packages/sqlalchemy/sql/visitors.py", line 661, in traverse_single
    return meth(obj, **kw)
  File "/usr/local/lib/python3.13/site-packages/sqlalchemy/sql/ddl.py", line 984, in visit_metadata
    self.traverse_single(
    ~~~~~~~~~~~~~~~~~~~~^
        table,
        ^^^^^^
    ...<2 lines>...
        _is_metadata_operation=True,
        ^^^^^^^^^^^^^^^^^^^^^^^^^^^^
    )
    ^
  File "/usr/local/lib/python3.13/site-packages/sqlalchemy/sql/visitors.py", line 661, in traverse_single
    return meth(obj, **kw)
  File "/usr/local/lib/python3.13/site-packages/sqlalchemy/sql/ddl.py", line 1026, in visit_table
    self.traverse_single(index, create_ok=True)
    ~~~~~~~~~~~~~~~~~~~~^^^^^^^^^^^^^^^^^^^^^^^
  File "/usr/local/lib/python3.13/site-packages/sqlalchemy/sql/visitors.py", line 661, in traverse_single
    return meth(obj, **kw)
  File "/usr/local/lib/python3.13/site-packages/sqlalchemy/sql/ddl.py", line 1063, in visit_index
    CreateIndex(index)._invoke_with(self.connection)
    ~~~~~~~~~~~~~~~~~~~~~~~~~~~~~~~^^^^^^^^^^^^^^^^^
  File "/usr/local/lib/python3.13/site-packages/sqlalchemy/sql/ddl.py", line 321, in _invoke_with
    return bind.execute(self)
           ~~~~~~~~~~~~^^^^^^
  File "/usr/local/lib/python3.13/site-packages/sqlalchemy/engine/base.py", line 1419, in execute
    return meth(
        self,
        distilled_parameters,
        execution_options or NO_OPTIONS,
    )
  File "/usr/local/lib/python3.13/site-packages/sqlalchemy/sql/ddl.py", line 187, in _execute_on_connection
    return connection._execute_ddl(
           ~~~~~~~~~~~~~~~~~~~~~~~^
        self, distilled_params, execution_options
        ^^^^^^^^^^^^^^^^^^^^^^^^^^^^^^^^^^^^^^^^^
    )
    ^
  File "/usr/local/lib/python3.13/site-packages/sqlalchemy/engine/base.py", line 1530, in _execute_ddl
    ret = self._execute_context(
        dialect,
    ...<4 lines>...
        compiled,
    )
  File "/usr/local/lib/python3.13/site-packages/sqlalchemy/engine/base.py", line 1846, in _execute_context
    return self._exec_single_context(
           ~~~~~~~~~~~~~~~~~~~~~~~~~^
        dialect, context, statement, parameters
        ^^^^^^^^^^^^^^^^^^^^^^^^^^^^^^^^^^^^^^^
    )
    ^
  File "/usr/local/lib/python3.13/site-packages/sqlalchemy/engine/base.py", line 1986, in _exec_single_context
    self._handle_dbapi_exception(
    ~~~~~~~~~~~~~~~~~~~~~~~~~~~~^
        e, str_statement, effective_parameters, cursor, context
        ^^^^^^^^^^^^^^^^^^^^^^^^^^^^^^^^^^^^^^^^^^^^^^^^^^^^^^^
    )
    ^
  File "/usr/local/lib/python3.13/site-packages/sqlalchemy/engine/base.py", line 2355, in _handle_dbapi_exception
    raise sqlalchemy_exception.with_traceback(exc_info[2]) from e
  File "/usr/local/lib/python3.13/site-packages/sqlalchemy/engine/base.py", line 1967, in _exec_single_context
    self.dialect.do_execute(
    ~~~~~~~~~~~~~~~~~~~~~~~^
        cursor, str_statement, effective_parameters, context
        ^^^^^^^^^^^^^^^^^^^^^^^^^^^^^^^^^^^^^^^^^^^^^^^^^^^^
    )
    ^
  File "/usr/local/lib/python3.13/site-packages/sqlalchemy/engine/default.py", line 951, in do_execute
    cursor.execute(statement, parameters)
    ~~~~~~~~~~~~~~^^^^^^^^^^^^^^^^^^^^^^^
sqlalchemy.exc.ProgrammingError: (psycopg2.errors.DuplicateTable) relation "idx_timestamp" already exists
[SQL: CREATE INDEX idx_timestamp ON request_logs (timestamp)]
(Background on this error at: https://sqlalche.me/e/20/f405)
ERROR:    Application startup failed. Exiting.
ERROR:asyncio:an error occurred during closing of asynchronous generator <async_generator object streamablehttp_client at 0x74cfe82b2150>
asyncgen: <async_generator object streamablehttp_client at 0x74cfe82b2150>
  + Exception Group Traceback (most recent call last):
  |   File "/usr/local/lib/python3.13/site-packages/anyio/_backends/_asyncio.py", line 772, in __aexit__
  |     raise BaseExceptionGroup(
  |         "unhandled errors in a TaskGroup", self._exceptions
  |     ) from None
  | BaseExceptionGroup: unhandled errors in a TaskGroup (1 sub-exception)
  +-+---------------- 1 ----------------
    | Traceback (most recent call last):
    |   File "/usr/local/lib/python3.13/site-packages/mcp/client/streamable_http.py", line 492, in streamablehttp_client
    |     yield (
    |     ...<3 lines>...
    |     )
    | GeneratorExit
    +------------------------------------
During handling of the above exception, another exception occurred:
Traceback (most recent call last):
  File "/usr/local/lib/python3.13/site-packages/mcp/client/streamable_http.py", line 464, in streamablehttp_client
    async with anyio.create_task_group() as tg:
               ~~~~~~~~~~~~~~~~~~~~~~~^^
  File "/usr/local/lib/python3.13/site-packages/anyio/_backends/_asyncio.py", line 778, in __aexit__
    if self.cancel_scope.__exit__(type(exc), exc, exc.__traceback__):
       ~~~~~~~~~~~~~~~~~~~~~~~~~~^^^^^^^^^^^^^^^^^^^^^^^^^^^^^^^^^^^
  File "/usr/local/lib/python3.13/site-packages/anyio/_backends/_asyncio.py", line 457, in __exit__
    raise RuntimeError(
    ...<2 lines>...
    )
RuntimeError: Attempted to exit cancel scope in a different task than it was entered in
