INFO:app.routes.test_routes:Fetching saved tests for user admin (category: client)
ERROR:app.routes.test_routes:Error fetching tests for user admin: 2 validation errors for TestResponse
server_id
  Input should be a valid string [type=string_type, input_value=None, input_type=NoneType]
    For further information visit https://errors.pydantic.dev/2.11/v/string_type
tool_name
  Input should be a valid string [type=string_type, input_value=None, input_type=NoneType]
    For further information visit https://errors.pydantic.dev/2.11/v/string_type
Traceback (most recent call last):
  File "/app/app/routes/test_routes.py", line 120, in get_saved_tests
    response.append(TestResponse(
                    ~~~~~~~~~~~~^
        id=test.id,
        ^^^^^^^^^^^
    ...<2 lines>...
        **test_data
        ^^^^^^^^^^^
    ))
    ^
  File "/usr/local/lib/python3.13/site-packages/pydantic/main.py", line 253, in __init__
    validated_self = self.__pydantic_validator__.validate_python(data, self_instance=self)
pydantic_core._pydantic_core.ValidationError: 2 validation errors for TestResponse
server_id
  Input should be a valid string [type=string_type, input_value=None, input_type=NoneType]
    For further information visit https://errors.pydantic.dev/2.11/v/string_type
tool_name
  Input should be a valid string [type=string_type, input_value=None, input_type=NoneType]
    For further information visit https://errors.pydantic.dev/2.11/v/string_type
